<?xml version="1.0" ?>
<!-- =================================================================================== -->
<!-- |    This document was autogenerated by xacro from car.xacro                      | -->
<!-- |    EDITING THIS FILE BY HAND IS NOT RECOMMENDED                                 | -->
<!-- =================================================================================== -->
<robot name="car">
  <material name="silver">
    <color rgba="0.700 0.700 0.700 1.000"/>
  </material>
  <transmission name="Revolute 13_tran">
    <type>transmission_interface/SimpleTransmission</type>
    <joint name="Revolute 13">
      <hardwareInterface>hardware_interface/EffortJointInterface</hardwareInterface>
    </joint>
    <actuator name="Revolute 13_actr">
      <hardwareInterface>hardware_interface/EffortJointInterface</hardwareInterface>
      <mechanicalReduction>1</mechanicalReduction>
    </actuator>
  </transmission>
  <transmission name="Revolute 14_tran">
    <type>transmission_interface/SimpleTransmission</type>
    <joint name="Revolute 14">
      <hardwareInterface>hardware_interface/EffortJointInterface</hardwareInterface>
    </joint>
    <actuator name="Revolute 14_actr">
      <hardwareInterface>hardware_interface/EffortJointInterface</hardwareInterface>
      <mechanicalReduction>1</mechanicalReduction>
    </actuator>
  </transmission>
  <transmission name="Revolute 15_tran">
    <type>transmission_interface/SimpleTransmission</type>
    <joint name="Revolute 15">
      <hardwareInterface>hardware_interface/EffortJointInterface</hardwareInterface>
    </joint>
    <actuator name="Revolute 15_actr">
      <hardwareInterface>hardware_interface/EffortJointInterface</hardwareInterface>
      <mechanicalReduction>1</mechanicalReduction>
    </actuator>
  </transmission>
  <transmission name="Revolute 16_tran">
    <type>transmission_interface/SimpleTransmission</type>
    <joint name="Revolute 16">
      <hardwareInterface>hardware_interface/EffortJointInterface</hardwareInterface>
    </joint>
    <actuator name="Revolute 16_actr">
      <hardwareInterface>hardware_interface/EffortJointInterface</hardwareInterface>
      <mechanicalReduction>1</mechanicalReduction>
    </actuator>
  </transmission>
  <transmission name="Revolute 17_tran">
    <type>transmission_interface/SimpleTransmission</type>
    <joint name="Revolute 17">
      <hardwareInterface>hardware_interface/EffortJointInterface</hardwareInterface>
    </joint>
    <actuator name="Revolute 17_actr">
      <hardwareInterface>hardware_interface/EffortJointInterface</hardwareInterface>
      <mechanicalReduction>1</mechanicalReduction>
    </actuator>
  </transmission>
  <transmission name="Revolute 19_tran">
    <type>transmission_interface/SimpleTransmission</type>
    <joint name="Revolute 19">
      <hardwareInterface>hardware_interface/EffortJointInterface</hardwareInterface>
    </joint>
    <actuator name="Revolute 19_actr">
      <hardwareInterface>hardware_interface/EffortJointInterface</hardwareInterface>
      <mechanicalReduction>1</mechanicalReduction>
    </actuator>
  </transmission>
  <transmission name="Revolute 21_tran">
    <type>transmission_interface/SimpleTransmission</type>
    <joint name="Revolute 21">
      <hardwareInterface>hardware_interface/EffortJointInterface</hardwareInterface>
    </joint>
    <actuator name="Revolute 21_actr">
      <hardwareInterface>hardware_interface/EffortJointInterface</hardwareInterface>
      <mechanicalReduction>1</mechanicalReduction>
    </actuator>
  </transmission>
  <transmission name="Revolute 22_tran">
    <type>transmission_interface/SimpleTransmission</type>
    <joint name="Revolute 22">
      <hardwareInterface>hardware_interface/EffortJointInterface</hardwareInterface>
    </joint>
    <actuator name="Revolute 22_actr">
      <hardwareInterface>hardware_interface/EffortJointInterface</hardwareInterface>
      <mechanicalReduction>1</mechanicalReduction>
    </actuator>
  </transmission>
  <gazebo>
    <plugin filename="libgazebo_ros_control.so" name="control"/>
  </gazebo>
  <gazebo reference="base_link">
    <material>Gazebo/Silver</material>
    <mu1>0.2</mu1>
    <mu2>0.2</mu2>
    <self_collide>true</self_collide>
    <gravity>true</gravity>
  </gazebo>
  <gazebo reference="direction_back_right_1">
    <material>Gazebo/Silver</material>
    <mu1>0.2</mu1>
    <mu2>0.2</mu2>
    <self_collide>true</self_collide>
  </gazebo>
  <gazebo reference="direction_back_left_1">
    <material>Gazebo/Silver</material>
    <mu1>0.2</mu1>
    <mu2>0.2</mu2>
    <self_collide>true</self_collide>
  </gazebo>
  <gazebo reference="direction_front_left_1">
    <material>Gazebo/Silver</material>
    <mu1>0.2</mu1>
    <mu2>0.2</mu2>
    <self_collide>true</self_collide>
  </gazebo>
  <gazebo reference="direction_front_right_1">
    <material>Gazebo/Silver</material>
    <mu1>0.2</mu1>
    <mu2>0.2</mu2>
    <self_collide>true</self_collide>
  </gazebo>
  <gazebo reference="rim_back_right_1">
    <material>Gazebo/Silver</material>
    <mu1>0.2</mu1>
    <mu2>0.2</mu2>
    <self_collide>true</self_collide>
  </gazebo>
  <gazebo reference="tire_back_right_1">
    <material>Gazebo/Silver</material>
    <mu1>0.2</mu1>
    <mu2>0.2</mu2>
    <self_collide>true</self_collide>
  </gazebo>
  <gazebo reference="rim_back_left_1">
    <material>Gazebo/Silver</material>
    <mu1>0.2</mu1>
    <mu2>0.2</mu2>
    <self_collide>true</self_collide>
  </gazebo>
  <gazebo reference="tire_back_left_1">
    <material>Gazebo/Silver</material>
    <mu1>0.2</mu1>
    <mu2>0.2</mu2>
    <self_collide>true</self_collide>
  </gazebo>
  <gazebo reference="rim_front_left_1">
    <material>Gazebo/Silver</material>
    <mu1>0.2</mu1>
    <mu2>0.2</mu2>
    <self_collide>true</self_collide>
  </gazebo>
  <gazebo reference="rim_front_right_1">
    <material>Gazebo/Silver</material>
    <mu1>0.2</mu1>
    <mu2>0.2</mu2>
    <self_collide>true</self_collide>
  </gazebo>
  <gazebo reference="tire_front_right_1">
    <material>Gazebo/Silver</material>
    <mu1>0.2</mu1>
    <mu2>0.2</mu2>
    <self_collide>true</self_collide>
  </gazebo>
  <gazebo reference="tire_front_left_1">
    <material>Gazebo/Silver</material>
    <mu1>0.2</mu1>
    <mu2>0.2</mu2>
    <self_collide>true</self_collide>
  </gazebo>
  <link name="base_link">
    <inertial>
      <origin rpy="0 0 0" xyz="1.2499999999999978 0.7500000000000009 -0.2545254750760079"/>
      <mass value="269.08335757252974"/>
      <inertia ixx="59.92484" ixy="-0.0" ixz="-0.0" iyy="164.14927" iyz="0.0" izz="209.699486"/>
    </inertial>
    <visual>
      <origin rpy="0 0 0" xyz="0 0 0"/>
      <geometry>
        <mesh filename="file:///home/rhobtor/Reactive_navegation/Reactive-Navegation/workspace/install/car/share/car/meshes/base_link.stl" scale="0.001 0.001 0.001"/>
      </geometry>
      <material name="silver"/>
    </visual>
    <collision>
      <origin rpy="0 0 0" xyz="0 0 0"/>
      <geometry>
        <mesh filename="file:///home/rhobtor/Reactive_navegation/Reactive-Navegation/workspace/install/car/share/car/meshes/base_link.stl" scale="0.001 0.001 0.001"/>
      </geometry>
    </collision>
  </link>
  <link name="direction_back_right_1">
    <inertial>
      <origin rpy="0 0 0" xyz="3.3409086608315874e-10 -0.0928245439091594 2.3407225085980699e-07"/>
      <mass value="8.30107936784585"/>
      <inertia ixx="0.025244" ixy="-0.0" ixz="-0.0" iyy="0.013095" iyz="-0.0" izz="0.028812"/>
    </inertial>
    <visual>
      <origin rpy="0 0 0" xyz="-0.35 0.07 0.481229"/>
      <geometry>
        <mesh filename="file:///home/rhobtor/Reactive_navegation/Reactive-Navegation/workspace/install/car/share/car/meshes/direction_back_right_1.stl" scale="0.001 0.001 0.001"/>
      </geometry>
      <material name="silver"/>
    </visual>
    <collision>
      <origin rpy="0 0 0" xyz="-0.35 0.07 0.481229"/>
      <geometry>
        <mesh filename="file:///home/rhobtor/Reactive_navegation/Reactive-Navegation/workspace/install/car/share/car/meshes/direction_back_right_1.stl" scale="0.001 0.001 0.001"/>
      </geometry>
    </collision>
  </link>
  <link name="direction_back_left_1">
    <inertial>
      <origin rpy="0 0 0" xyz="-3.885780586188048e-16 0.09282454447738075 2.3407225102634044e-07"/>
      <mass value="8.301079315724648"/>
      <inertia ixx="0.025244" ixy="0.0" ixz="0.0" iyy="0.013095" iyz="0.0" izz="0.028812"/>
    </inertial>
    <visual>
      <origin rpy="0 0 0" xyz="-0.35 -1.57 0.481229"/>
      <geometry>
        <mesh filename="file:///home/rhobtor/Reactive_navegation/Reactive-Navegation/workspace/install/car/share/car/meshes/direction_back_left_1.stl" scale="0.001 0.001 0.001"/>
      </geometry>
      <material name="silver"/>
    </visual>
    <collision>
      <origin rpy="0 0 0" xyz="-0.35 -1.57 0.481229"/>
      <geometry>
        <mesh filename="file:///home/rhobtor/Reactive_navegation/Reactive-Navegation/workspace/install/car/share/car/meshes/direction_back_left_1.stl" scale="0.001 0.001 0.001"/>
      </geometry>
    </collision>
  </link>
  <link name="direction_front_left_1">
    <inertial>
      <origin rpy="0 0 0" xyz="4.440892098500626e-16 0.09282454447738075 2.3407225091531814e-07"/>
      <mass value="8.301079315724627"/>
      <inertia ixx="0.025244" ixy="0.0" ixz="0.0" iyy="0.013095" iyz="0.0" izz="0.028812"/>
    </inertial>
    <visual>
      <origin rpy="0 0 0" xyz="-2.15 -1.57 0.481229"/>
      <geometry>
        <mesh filename="file:///home/rhobtor/Reactive_navegation/Reactive-Navegation/workspace/install/car/share/car/meshes/direction_front_left_1.stl" scale="0.001 0.001 0.001"/>
      </geometry>
      <material name="silver"/>
    </visual>
    <collision>
      <origin rpy="0 0 0" xyz="-2.15 -1.57 0.481229"/>
      <geometry>
        <mesh filename="file:///home/rhobtor/Reactive_navegation/Reactive-Navegation/workspace/install/car/share/car/meshes/direction_front_left_1.stl" scale="0.001 0.001 0.001"/>
      </geometry>
    </collision>
  </link>
  <link name="direction_front_right_1">
    <inertial>
      <origin rpy="0 0 0" xyz="2.220446049250313e-15 -0.09282454447738067 2.3407225041571778e-07"/>
      <mass value="8.301079315724627"/>
      <inertia ixx="0.025244" ixy="-0.0" ixz="-0.0" iyy="0.013095" iyz="0.0" izz="0.028812"/>
    </inertial>
    <visual>
      <origin rpy="0 0 0" xyz="-2.15 0.07 0.481229"/>
      <geometry>
        <mesh filename="file:///home/rhobtor/Reactive_navegation/Reactive-Navegation/workspace/install/car/share/car/meshes/direction_front_right_1.stl" scale="0.001 0.001 0.001"/>
      </geometry>
      <material name="silver"/>
    </visual>
    <collision>
      <origin rpy="0 0 0" xyz="-2.15 0.07 0.481229"/>
      <geometry>
        <mesh filename="file:///home/rhobtor/Reactive_navegation/Reactive-Navegation/workspace/install/car/share/car/meshes/direction_front_right_1.stl" scale="0.001 0.001 0.001"/>
      </geometry>
    </collision>
  </link>
  <link name="rim_back_right_1">
    <inertial>
      <origin rpy="0 0 0" xyz="-6.193390829078993e-07 -0.0444583218626792 -3.5654687319808254e-06"/>
      <mass value="35.26125455495801"/>
      <inertia ixx="0.833786" ixy="-1e-06" ixz="-3e-06" iyy="1.48872" iyz="-3e-06" izz="0.833785"/>
    </inertial>
    <visual>
      <origin rpy="0 0 0" xyz="-0.35 0.225 0.481229"/>
      <geometry>
        <mesh filename="file:///home/rhobtor/Reactive_navegation/Reactive-Navegation/workspace/install/car/share/car/meshes/rim_back_right_1.stl" scale="0.001 0.001 0.001"/>
      </geometry>
      <material name="silver"/>
    </visual>
    <collision>
      <origin rpy="0 0 0" xyz="-0.35 0.225 0.481229"/>
      <geometry>
        <mesh filename="file:///home/rhobtor/Reactive_navegation/Reactive-Navegation/workspace/install/car/share/car/meshes/rim_back_right_1.stl" scale="0.001 0.001 0.001"/>
      </geometry>
    </collision>
  </link>
  <link name="tire_back_right_1">
    <inertial>
      <origin rpy="0 0 0" xyz="3.3306690738754696e-16 1.865424177349695e-07 2.3407225080429583e-07"/>
      <mass value="72.81552294350425"/>
      <inertia ixx="4.088543" ixy="-0.0" ixz="-0.0" iyy="7.430415" iyz="0.0" izz="4.088543"/>
    </inertial>
    <visual>
      <origin rpy="0 0 0" xyz="-0.35 0.272622 0.481229"/>
      <geometry>
        <mesh filename="file:///home/rhobtor/Reactive_navegation/Reactive-Navegation/workspace/install/car/share/car/meshes/tire_back_right_1.stl" scale="0.001 0.001 0.001"/>
      </geometry>
      <material name="silver"/>
    </visual>
    <collision>
      <origin rpy="0 0 0" xyz="-0.35 0.272622 0.481229"/>
      <geometry>
        <mesh filename="file:///home/rhobtor/Reactive_navegation/Reactive-Navegation/workspace/install/car/share/car/meshes/tire_back_right_1.stl" scale="0.001 0.001 0.001"/>
      </geometry>
    </collision>
  </link>
  <link name="rim_back_left_1">
    <inertial>
      <origin rpy="0 0 0" xyz="-6.19339082796877e-07 0.04445832186264642 4.033613232867772e-06"/>
      <mass value="35.26125455495529"/>
      <inertia ixx="0.833786" ixy="1e-06" ixz="3e-06" iyy="1.48872" iyz="-3e-06" izz="0.833785"/>
    </inertial>
    <visual>
      <origin rpy="0 0 0" xyz="-0.35 -1.725 0.481229"/>
      <geometry>
        <mesh filename="file:///home/rhobtor/Reactive_navegation/Reactive-Navegation/workspace/install/car/share/car/meshes/rim_back_left_1.stl" scale="0.001 0.001 0.001"/>
      </geometry>
      <material name="silver"/>
    </visual>
    <collision>
      <origin rpy="0 0 0" xyz="-0.35 -1.725 0.481229"/>
      <geometry>
        <mesh filename="file:///home/rhobtor/Reactive_navegation/Reactive-Navegation/workspace/install/car/share/car/meshes/rim_back_left_1.stl" scale="0.001 0.001 0.001"/>
      </geometry>
    </collision>
  </link>
  <link name="tire_back_left_1">
    <inertial>
      <origin rpy="0 0 0" xyz="3.3306690738754696e-16 -1.8654241507043423e-07 2.3407225080429583e-07"/>
      <mass value="72.81552294350425"/>
      <inertia ixx="4.088543" ixy="-0.0" ixz="-0.0" iyy="7.430415" iyz="0.0" izz="4.088543"/>
    </inertial>
    <visual>
      <origin rpy="0 0 0" xyz="-0.35 -1.772622 0.481229"/>
      <geometry>
        <mesh filename="file:///home/rhobtor/Reactive_navegation/Reactive-Navegation/workspace/install/car/share/car/meshes/tire_back_left_1.stl" scale="0.001 0.001 0.001"/>
      </geometry>
      <material name="silver"/>
    </visual>
    <collision>
      <origin rpy="0 0 0" xyz="-0.35 -1.772622 0.481229"/>
      <geometry>
        <mesh filename="file:///home/rhobtor/Reactive_navegation/Reactive-Navegation/workspace/install/car/share/car/meshes/tire_back_left_1.stl" scale="0.001 0.001 0.001"/>
      </geometry>
    </collision>
  </link>
  <link name="rim_front_left_1">
    <inertial>
      <origin rpy="0 0 0" xyz="-6.193390835740331e-07 0.04445832186254606 4.033613235310263e-06"/>
      <mass value="35.26125455494993"/>
      <inertia ixx="0.833786" ixy="1e-06" ixz="3e-06" iyy="1.48872" iyz="-3e-06" izz="0.833785"/>
    </inertial>
    <visual>
      <origin rpy="0 0 0" xyz="-2.15 -1.725 0.481229"/>
      <geometry>
        <mesh filename="file:///home/rhobtor/Reactive_navegation/Reactive-Navegation/workspace/install/car/share/car/meshes/rim_front_left_1.stl" scale="0.001 0.001 0.001"/>
      </geometry>
      <material name="silver"/>
    </visual>
    <collision>
      <origin rpy="0 0 0" xyz="-2.15 -1.725 0.481229"/>
      <geometry>
        <mesh filename="file:///home/rhobtor/Reactive_navegation/Reactive-Navegation/workspace/install/car/share/car/meshes/rim_front_left_1.stl" scale="0.001 0.001 0.001"/>
      </geometry>
    </collision>
  </link>
  <link name="rim_front_right_1">
    <inertial>
      <origin rpy="0 0 0" xyz="-6.193390862385684e-07 -0.044458321862509836 -3.5654687342567826e-06"/>
      <mass value="35.26125455495071"/>
      <inertia ixx="0.833786" ixy="-1e-06" ixz="-3e-06" iyy="1.48872" iyz="-3e-06" izz="0.833785"/>
    </inertial>
    <visual>
      <origin rpy="0 0 0" xyz="-2.15 0.225 0.481229"/>
      <geometry>
        <mesh filename="file:///home/rhobtor/Reactive_navegation/Reactive-Navegation/workspace/install/car/share/car/meshes/rim_front_right_1.stl" scale="0.001 0.001 0.001"/>
      </geometry>
      <material name="silver"/>
    </visual>
    <collision>
      <origin rpy="0 0 0" xyz="-2.15 0.225 0.481229"/>
      <geometry>
        <mesh filename="file:///home/rhobtor/Reactive_navegation/Reactive-Navegation/workspace/install/car/share/car/meshes/rim_front_right_1.stl" scale="0.001 0.001 0.001"/>
      </geometry>
    </collision>
  </link>
  <link name="tire_front_right_1">
    <inertial>
      <origin rpy="0 0 0" xyz="1.3322676295501878e-15 1.865424186231479e-07 2.3407225080429583e-07"/>
      <mass value="72.81552294350425"/>
      <inertia ixx="4.088543" ixy="-0.0" ixz="0.0" iyy="7.430415" iyz="0.0" izz="4.088543"/>
    </inertial>
    <visual>
      <origin rpy="0 0 0" xyz="-2.15 0.272622 0.481229"/>
      <geometry>
        <mesh filename="file:///home/rhobtor/Reactive_navegation/Reactive-Navegation/workspace/install/car/share/car/meshes/tire_front_right_1.stl" scale="0.001 0.001 0.001"/>
      </geometry>
      <material name="silver"/>
    </visual>
    <collision>
      <origin rpy="0 0 0" xyz="-2.15 0.272622 0.481229"/>
      <geometry>
        <mesh filename="file:///home/rhobtor/Reactive_navegation/Reactive-Navegation/workspace/install/car/share/car/meshes/tire_front_right_1.stl" scale="0.001 0.001 0.001"/>
      </geometry>
    </collision>
  </link>
  <link name="tire_front_left_1">
    <inertial>
      <origin rpy="0 0 0" xyz="3.9968028886505635e-15 -1.8654242395221843e-07 2.3407225091531814e-07"/>
      <mass value="72.81552294350426"/>
      <inertia ixx="4.088543" ixy="0.0" ixz="-0.0" iyy="7.430415" iyz="0.0" izz="4.088543"/>
    </inertial>
    <visual>
      <origin rpy="0 0 0" xyz="-2.15 -1.772622 0.481229"/>
      <geometry>
        <mesh filename="file:///home/rhobtor/Reactive_navegation/Reactive-Navegation/workspace/install/car/share/car/meshes/tire_front_left_1.stl" scale="0.001 0.001 0.001"/>
      </geometry>
      <material name="silver"/>
    </visual>
    <collision>
      <origin rpy="0 0 0" xyz="-2.15 -1.772622 0.481229"/>
      <geometry>
        <mesh filename="file:///home/rhobtor/Reactive_navegation/Reactive-Navegation/workspace/install/car/share/car/meshes/tire_front_left_1.stl" scale="0.001 0.001 0.001"/>
      </geometry>
    </collision>
  </link>
  <joint name="Direction_right_back" type="continuous">
    <origin rpy="0 0 0" xyz="0.35 -0.07 -0.481229"/>
    <parent link="base_link"/>
    <child link="direction_back_right_1"/>
    <axis xyz="0.0 0.0 1.0"/>
  </joint>
  <joint name="Direction_left_back" type="continuous">
    <origin rpy="0 0 0" xyz="0.35 1.57 -0.481229"/>
    <parent link="base_link"/>
    <child link="direction_back_left_1"/>
    <axis xyz="0.0 0.0 1.0"/>
  </joint>
  <joint name="Direction_left_front" type="revolute">
    <origin rpy="0 0 0" xyz="2.15 1.57 -0.481229"/>
    <parent link="base_link"/>
    <child link="direction_front_left_1"/>
    <axis xyz="0.0 0.0 -1.0"/>
    <limit effort="10.0" lower="-1.57" upper="1.57" velocity="1.0"/>
  </joint>
  <joint name="Direction_right_front" type="revolute">
    <origin rpy="0 0 0" xyz="2.15 -0.07 -0.481229"/>
    <parent link="base_link"/>
    <child link="direction_front_right_1"/>
    <axis xyz="0.0 0.0 -1.0"/>
    <limit effort="1000.0" lower="-1.57" upper="1.57" velocity="100.0"/>
  </joint>
  <joint name="Revolute_right_back" type="continuous">
    <origin rpy="0 0 0" xyz="0.0 -0.155 0.0"/>
    <parent link="direction_back_right_1"/>
    <child link="rim_back_right_1"/>
    <axis xyz="0.0 -1.0 0.0"/>
  </joint>
  <joint name="Rigid 18" type="fixed">
    <origin rpy="0 0 0" xyz="0.0 -0.047622 0.0"/>
    <parent link="rim_back_right_1"/>
    <child link="tire_back_right_1"/>
  </joint>
  <joint name="Revolute_left_back" type="continuous">
    <origin rpy="0 0 0" xyz="0.0 0.155 0.0"/>
    <parent link="direction_back_left_1"/>
    <child link="rim_back_left_1"/>
    <axis xyz="0.0 1.0 0.0"/>
  </joint>
  <joint name="Rigid 20" type="fixed">
    <origin rpy="0 0 0" xyz="0.0 0.047622 0.0"/>
    <parent link="rim_back_left_1"/>
    <child link="tire_back_left_1"/>
  </joint>
  <joint name="Revolute_left_front" type="continuous">
    <origin rpy="0 0 0" xyz="0.0 0.155 0.0"/>
    <parent link="direction_front_left_1"/>
    <child link="rim_front_left_1"/>
    <axis xyz="0.0 1.0 0.0"/>
  </joint>
  <joint name="Revolute_right_front" type="continuous">
    <origin rpy="0 0 0" xyz="0.0 -0.155 0.0"/>
    <parent link="direction_front_right_1"/>
    <child link="rim_front_right_1"/>
    <axis xyz="0.0 -1.0 0.0"/>
  </joint>
  <joint name="Rigid 23" type="fixed">
    <origin rpy="0 0 0" xyz="0.0 -0.047622 0.0"/>
    <parent link="rim_front_right_1"/>
    <child link="tire_front_right_1"/>
  </joint>
  <joint name="Rigid 24" type="fixed">
    <origin rpy="0 0 0" xyz="0.0 0.047622 0.0"/>
    <parent link="rim_front_left_1"/>
    <child link="tire_front_left_1"/>
  </joint>
  <gazebo>
    <plugin filename="libcontrol_plugin.so" name="control_plugin">
      <joint_name>Direction_right_front</joint_name>
    </plugin>
  </gazebo>
</robot>
