<?xml version="1.0" ?>
<robot name="car" xmlns:xacro="http://www.ros.org/wiki/xacro">

<xacro:include filename="$(find car)/urdf/materials.xacro" />
<xacro:include filename="$(find car)/urdf/car.trans" />
<xacro:include filename="$(find car)/urdf/car.gazebo" />
<xacro:include filename="$(find car)/urdf/camara.plugin.xacro" />
<xacro:include filename="$(find car)/urdf/lidar.plugin.xacro" />

<link name="base_link">
  <inertial>
    <origin xyz="1.2499999999999998 0.75 -0.45" rpy="0 0 0"/>
    <mass value="195.94086385796686"/>
    <inertia ixx="0.825102" iyy="42.139945" izz="42.62574" ixy="-0.0" iyz="0.0" ixz="0.0"/>
  </inertial>
  <visual>
    <origin xyz="0 0 0" rpy="0 0 0"/>
    <geometry>
      <mesh filename="file://$(find car)/meshes/base_link.stl" scale="0.001 0.001 0.001"/>
    </geometry>
    <material name="silver"/>
  </visual>
  <collision>
    <origin xyz="0 0 0" rpy="0 0 0"/>
    <geometry>
      <mesh filename="file://$(find car)/meshes/base_link.stl" scale="0.001 0.001 0.001"/>
    </geometry>
  </collision>
</link>

<link name="suspension_front_right_1">
  <inertial>
    <origin xyz="0.0 -0.4032961129921663 0.0" rpy="0 0 0"/>
    <mass value="33.21861256094089"/>
    <inertia ixx="1.897101" iyy="0.053443" izz="1.887366" ixy="0.0" iyz="0.0" ixz="-0.0"/>
  </inertial>
  <visual>
    <origin xyz="-1.925 -0.625 0.45" rpy="0 0 0"/>
    <geometry>
      <mesh filename="file://$(find car)/meshes/suspension_front_right_1.stl" scale="0.001 0.001 0.001"/>
    </geometry>
    <material name="silver"/>
  </visual>
  <collision>
    <origin xyz="-1.925 -0.625 0.45" rpy="0 0 0"/>
    <geometry>
      <mesh filename="file://$(find car)/meshes/suspension_front_right_1.stl" scale="0.001 0.001 0.001"/>
    </geometry>
  </collision>
</link>

<link name="suspension_front_left__1">
  <inertial>
    <origin xyz="-2.220446049250313e-16 0.40329611299216594 0.0" rpy="0 0 0"/>
    <mass value="33.2186125609409"/>
    <inertia ixx="1.897101" iyy="0.053443" izz="1.887366" ixy="0.0" iyz="0.0" ixz="-0.0"/>
  </inertial>
  <visual>
    <origin xyz="-1.925 -0.875 0.45" rpy="0 0 0"/>
    <geometry>
      <mesh filename="file://$(find car)/meshes/suspension_front_left__1.stl" scale="0.001 0.001 0.001"/>
    </geometry>
    <material name="silver"/>
  </visual>
  <collision>
    <origin xyz="-1.925 -0.875 0.45" rpy="0 0 0"/>
    <geometry>
      <mesh filename="file://$(find car)/meshes/suspension_front_left__1.stl" scale="0.001 0.001 0.001"/>
    </geometry>
  </collision>
</link>

<link name="suspension_back_right_1">
  <inertial>
    <origin xyz="0.0 -0.4032961129921663 0.0" rpy="0 0 0"/>
    <mass value="33.21861256094089"/>
    <inertia ixx="1.897101" iyy="0.053443" izz="1.887366" ixy="0.0" iyz="0.0" ixz="0.0"/>
  </inertial>
  <visual>
    <origin xyz="-0.575 -0.625 0.45" rpy="0 0 0"/>
    <geometry>
      <mesh filename="file://$(find car)/meshes/suspension_back_right_1.stl" scale="0.001 0.001 0.001"/>
    </geometry>
    <material name="silver"/>
  </visual>
  <collision>
    <origin xyz="-0.575 -0.625 0.45" rpy="0 0 0"/>
    <geometry>
      <mesh filename="file://$(find car)/meshes/suspension_back_right_1.stl" scale="0.001 0.001 0.001"/>
    </geometry>
  </collision>
</link>

<link name="suspension_back_left_1">
  <inertial>
    <origin xyz="1.1102230246251565e-16 0.40329611299216617 0.0" rpy="0 0 0"/>
    <mass value="33.2186125609409"/>
    <inertia ixx="1.897101" iyy="0.053443" izz="1.887366" ixy="0.0" iyz="0.0" ixz="-0.0"/>
  </inertial>
  <visual>
    <origin xyz="-0.575 -0.875 0.45" rpy="0 0 0"/>
    <geometry>
      <mesh filename="file://$(find car)/meshes/suspension_back_left_1.stl" scale="0.001 0.001 0.001"/>
    </geometry>
    <material name="silver"/>
  </visual>
  <collision>
    <origin xyz="-0.575 -0.875 0.45" rpy="0 0 0"/>
    <geometry>
      <mesh filename="file://$(find car)/meshes/suspension_back_left_1.stl" scale="0.001 0.001 0.001"/>
    </geometry>
  </collision>
</link>

<link name="rim_back_left_1">
  <inertial>
    <origin xyz="-6.193390665876208e-07 0.04445832186276344 3.799540942373003e-06" rpy="0 0 0"/>
    <mass value="35.261254554957446"/>
    <inertia ixx="0.833786" iyy="1.48872" izz="0.833785" ixy="1e-06" iyz="-3e-06" ixz="3e-06"/>
  </inertial>
  <visual>
    <origin xyz="-0.58 -1.75 0.45" rpy="0 0 0"/>
    <geometry>
      <mesh filename="file://$(find car)/meshes/rim_back_left_1.stl" scale="0.001 0.001 0.001"/>
    </geometry>
    <material name="silver"/>
  </visual>
  <collision>
    <origin xyz="-0.58 -1.75 0.45" rpy="0 0 0"/>
    <geometry>
      <mesh filename="file://$(find car)/meshes/rim_back_left_1.stl" scale="0.001 0.001 0.001"/>
    </geometry>
  </collision>
</link>

<link name="rim_back_right_1">
  <inertial>
    <origin xyz="-6.19339130869534e-07 -0.04445832186276377 -3.799540955917724e-06" rpy="0 0 0"/>
    <mass value="35.26125455495827"/>
    <inertia ixx="0.833786" iyy="1.48872" izz="0.833785" ixy="-1e-06" iyz="-3e-06" ixz="-3e-06"/>
  </inertial>
  <visual>
    <origin xyz="-0.58 0.25 0.45" rpy="0 0 0"/>
    <geometry>
      <mesh filename="file://$(find car)/meshes/rim_back_right_1.stl" scale="0.001 0.001 0.001"/>
    </geometry>
    <material name="silver"/>
  </visual>
  <collision>
    <origin xyz="-0.58 0.25 0.45" rpy="0 0 0"/>
    <geometry>
      <mesh filename="file://$(find car)/meshes/rim_back_right_1.stl" scale="0.001 0.001 0.001"/>
    </geometry>
  </collision>
</link>

<link name="rim_front_right_1">
  <inertial>
    <origin xyz="-6.193392563247357e-07 -0.04445832186276233 -3.799540938653756e-06" rpy="0 0 0"/>
    <mass value="35.2612545549612"/>
    <inertia ixx="0.833786" iyy="1.48872" izz="0.833785" ixy="-1e-06" iyz="-3e-06" ixz="-3e-06"/>
  </inertial>
  <visual>
    <origin xyz="-1.925 0.25 0.45" rpy="0 0 0"/>
    <geometry>
      <mesh filename="file://$(find car)/meshes/rim_front_right_1.stl" scale="0.001 0.001 0.001"/>
    </geometry>
    <material name="silver"/>
  </visual>
  <collision>
    <origin xyz="-1.925 0.25 0.45" rpy="0 0 0"/>
    <geometry>
      <mesh filename="file://$(find car)/meshes/rim_front_right_1.stl" scale="0.001 0.001 0.001"/>
    </geometry>
  </collision>
</link>

<link name="rim_front_left_1">
  <inertial>
    <origin xyz="-6.193391801634363e-07 0.044458321862759886 3.7995409425950477e-06" rpy="0 0 0"/>
    <mass value="35.26125455495683"/>
    <inertia ixx="0.833786" iyy="1.48872" izz="0.833785" ixy="1e-06" iyz="-3e-06" ixz="3e-06"/>
  </inertial>
  <visual>
    <origin xyz="-1.925 -1.75 0.45" rpy="0 0 0"/>
    <geometry>
      <mesh filename="file://$(find car)/meshes/rim_front_left_1.stl" scale="0.001 0.001 0.001"/>
    </geometry>
    <material name="silver"/>
  </visual>
  <collision>
    <origin xyz="-1.925 -1.75 0.45" rpy="0 0 0"/>
    <geometry>
      <mesh filename="file://$(find car)/meshes/rim_front_left_1.stl" scale="0.001 0.001 0.001"/>
    </geometry>
  </collision>
</link>

<link name="tire_front_right_1">
  <inertial>
    <origin xyz="-2.6645352591003757e-15 1.8654241801252525e-07 1.6653345369377348e-16" rpy="0 0 0"/>
    <mass value="72.81552294350315"/>
    <inertia ixx="4.088543" iyy="7.430415" izz="4.088543" ixy="0.0" iyz="-0.0" ixz="0.0"/>
  </inertial>
  <visual>
    <origin xyz="-1.925 0.297622 0.45" rpy="0 0 0"/>
    <geometry>
      <mesh filename="file://$(find car)/meshes/tire_front_right_1.stl" scale="0.001 0.001 0.001"/>
    </geometry>
    <material name="silver"/>
  </visual>
  <collision>
    <origin xyz="-1.925 0.297622 0.45" rpy="0 0 0"/>
    <geometry>
      <mesh filename="file://$(find car)/meshes/tire_front_right_1.stl" scale="0.001 0.001 0.001"/>
    </geometry>
  </collision>
</link>

<link name="tire_back_right_1">
  <inertial>
    <origin xyz="-9.325873406851315e-15 1.8654242434079649e-07 1.7208456881689926e-15" rpy="0 0 0"/>
    <mass value="72.81552294350364"/>
    <inertia ixx="4.088543" iyy="7.430415" izz="4.088543" ixy="0.0" iyz="-0.0" ixz="0.0"/>
  </inertial>
  <visual>
    <origin xyz="-0.58 0.297622 0.45" rpy="0 0 0"/>
    <geometry>
      <mesh filename="file://$(find car)/meshes/tire_back_right_1.stl" scale="0.001 0.001 0.001"/>
    </geometry>
    <material name="silver"/>
  </visual>
  <collision>
    <origin xyz="-0.58 0.297622 0.45" rpy="0 0 0"/>
    <geometry>
      <mesh filename="file://$(find car)/meshes/tire_back_right_1.stl" scale="0.001 0.001 0.001"/>
    </geometry>
  </collision>
</link>

<link name="tire_back_left_1">
  <inertial>
    <origin xyz="-4.6629367034256575e-15 -1.8654240641069464e-07 1.7763568394002505e-15" rpy="0 0 0"/>
    <mass value="72.8155229435052"/>
    <inertia ixx="4.088543" iyy="7.430415" izz="4.088543" ixy="0.0" iyz="-0.0" ixz="0.0"/>
  </inertial>
  <visual>
    <origin xyz="-0.58 -1.797622 0.45" rpy="0 0 0"/>
    <geometry>
      <mesh filename="file://$(find car)/meshes/tire_back_left_1.stl" scale="0.001 0.001 0.001"/>
    </geometry>
    <material name="silver"/>
  </visual>
  <collision>
    <origin xyz="-0.58 -1.797622 0.45" rpy="0 0 0"/>
    <geometry>
      <mesh filename="file://$(find car)/meshes/tire_back_left_1.stl" scale="0.001 0.001 0.001"/>
    </geometry>
  </collision>
</link>

<link name="tire_front_left_1">
  <inertial>
    <origin xyz="-1.1102230246251565e-14 -1.8654240641069464e-07 1.9984014443252818e-15" rpy="0 0 0"/>
    <mass value="72.81552294350463"/>
    <inertia ixx="4.088543" iyy="7.430415" izz="4.088543" ixy="0.0" iyz="-0.0" ixz="0.0"/>
  </inertial>
  <visual>
    <origin xyz="-1.925 -1.797622 0.45" rpy="0 0 0"/>
    <geometry>
      <mesh filename="file://$(find car)/meshes/tire_front_left_1.stl" scale="0.001 0.001 0.001"/>
    </geometry>
    <material name="silver"/>
  </visual>
  <collision>
    <origin xyz="-1.925 -1.797622 0.45" rpy="0 0 0"/>
    <geometry>
      <mesh filename="file://$(find car)/meshes/tire_front_left_1.stl" scale="0.001 0.001 0.001"/>
    </geometry>
  </collision>
</link>

<link name="direction_back_left_1">
  <inertial>
    <origin xyz="0.00201472265142022 0.07474229529205378 5.551115123125783e-17" rpy="0 0 0"/>
    <mass value="11.386858894419678"/>
    <inertia ixx="0.054235" iyy="0.024154" izz="0.06804" ixy="-0.00144" iyz="0.0" ixz="0.0"/>
  </inertial>
  <visual>
    <origin xyz="-0.575 -1.5875 0.45" rpy="0 0 0"/>
    <geometry>
      <mesh filename="file://$(find car)/meshes/direction_back_left_1.stl" scale="0.001 0.001 0.001"/>
    </geometry>
    <material name="silver"/>
  </visual>
  <collision>
    <origin xyz="-0.575 -1.5875 0.45" rpy="0 0 0"/>
    <geometry>
      <mesh filename="file://$(find car)/meshes/direction_back_left_1.stl" scale="0.001 0.001 0.001"/>
    </geometry>
  </collision>
</link>

<link name="direction_back_right_1">
  <inertial>
    <origin xyz="0.002014722651420442 -0.07474229529205342 0.0" rpy="0 0 0"/>
    <mass value="11.386858894419664"/>
    <inertia ixx="0.054235" iyy="0.024154" izz="0.06804" ixy="0.00144" iyz="0.0" ixz="-0.0"/>
  </inertial>
  <visual>
    <origin xyz="-0.575 0.0875 0.45" rpy="0 0 0"/>
    <geometry>
      <mesh filename="file://$(find car)/meshes/direction_back_right_1.stl" scale="0.001 0.001 0.001"/>
    </geometry>
    <material name="silver"/>
  </visual>
  <collision>
    <origin xyz="-0.575 0.0875 0.45" rpy="0 0 0"/>
    <geometry>
      <mesh filename="file://$(find car)/meshes/direction_back_right_1.stl" scale="0.001 0.001 0.001"/>
    </geometry>
  </collision>
</link>

<link name="direction_front_right_1">
  <inertial>
    <origin xyz="-2.220446049250313e-16 -0.07474229529205345 0.0" rpy="0 0 0"/>
    <mass value="11.386858894419674"/>
    <inertia ixx="0.054235" iyy="0.024086" izz="0.067971" ixy="0.0" iyz="0.0" ixz="0.0"/>
  </inertial>
  <visual>
    <origin xyz="-1.925 0.0875 0.45" rpy="0 0 0"/>
    <geometry>
      <mesh filename="file://$(find car)/meshes/direction_front_right_1.stl" scale="0.001 0.001 0.001"/>
    </geometry>
    <material name="silver"/>
  </visual>
  <collision>
    <origin xyz="-1.925 0.0875 0.45" rpy="0 0 0"/>
    <geometry>
      <mesh filename="file://$(find car)/meshes/direction_front_right_1.stl" scale="0.001 0.001 0.001"/>
    </geometry>
  </collision>
</link>

<link name="direction_front_left_1">
  <inertial>
    <origin xyz="2.220446049250313e-16 0.07474229529205334 5.551115123125783e-17" rpy="0 0 0"/>
    <mass value="11.386858894419714"/>
    <inertia ixx="0.054235" iyy="0.024086" izz="0.067971" ixy="-0.0" iyz="0.0" ixz="-0.0"/>
  </inertial>
  <visual>
    <origin xyz="-1.925 -1.5875 0.45" rpy="0 0 0"/>
    <geometry>
      <mesh filename="file://$(find car)/meshes/direction_front_left_1.stl" scale="0.001 0.001 0.001"/>
    </geometry>
    <material name="silver"/>
  </visual>
  <collision>
    <origin xyz="-1.925 -1.5875 0.45" rpy="0 0 0"/>
    <geometry>
      <mesh filename="file://$(find car)/meshes/direction_front_left_1.stl" scale="0.001 0.001 0.001"/>
    </geometry>
  </collision>
</link>

<link name="chasis_1">
  <inertial>
    <origin xyz="0.09238270773822022 -1.1102230246251565e-16 0.5327884318036318" rpy="0 0 0"/>
    <mass value="14235.910080029777"/>
    <inertia ixx="3772.896581" iyy="5428.125259" izz="8145.031104" ixy="0.0" iyz="-0.0" ixz="-431.237028"/>
  </inertial>
  <visual>
    <origin xyz="-1.25 -0.75 0.4" rpy="0 0 0"/>
    <geometry>
      <mesh filename="file://$(find car)/meshes/chasis_1.stl" scale="0.001 0.001 0.001"/>
    </geometry>
    <material name="silver"/>
  </visual>
  <collision>
    <origin xyz="-1.25 -0.75 0.4" rpy="0 0 0"/>
    <geometry>
      <mesh filename="file://$(find car)/meshes/chasis_1.stl" scale="0.001 0.001 0.001"/>
    </geometry>
  </collision>
</link>

<link name="Lidar">
  <inertial>
    <origin xyz="-6.661338147750939e-16 1.1102230246251565e-16 0.050000000000000266" rpy="0 0 0"/>
    <mass value="24.661502330679863"/>
    <inertia ixx="0.082205" iyy="0.082205" izz="0.123308" ixy="0.0" iyz="-0.0" ixz="0.0"/>
  </inertial>
  <visual>
    <origin xyz="-1.85 -0.75 -0.65" rpy="0 0 0"/>
    <geometry>
      <mesh filename="file://$(find car)/meshes/Component24_1.stl" scale="0.001 0.001 0.001"/>
    </geometry>
    <material name="silver"/>
  </visual>
  <collision>
    <origin xyz="-1.85 -0.75 -0.65" rpy="0 0 0"/>
    <geometry>
      <mesh filename="file://$(find car)/meshes/Component24_1.stl" scale="0.001 0.001 0.001"/>
    </geometry>
  </collision>
</link>

<link name="Camara">
  <inertial>
    <origin xyz="0.004642800215263865 0.0 0.0018567355153457643" rpy="0 0 0"/>
    <mass value="2.3549999999999622"/>
    <inertia ixx="0.019357" iyy="0.001982" izz="0.01795" ixy="-0.0" iyz="-0.0" ixz="0.00067"/>
  </inertial>
  <visual>
    <origin xyz="-2.175082 -0.75 -0.43922" rpy="0 0 0"/>
    <geometry>
      <mesh filename="file://$(find car)/meshes/Component25_1.stl" scale="0.001 0.001 0.001"/>
    </geometry>
    <material name="silver"/>
  </visual>
  <collision>
    <origin xyz="-2.175082 -0.75 -0.43922" rpy="0 0 0"/>
    <geometry>
      <mesh filename="file://$(find car)/meshes/Component25_1.stl" scale="0.001 0.001 0.001"/>
    </geometry>
  </collision>
</link>

<joint name="Revolute 1" type="fixed">
  <origin xyz="1.925 0.625 -0.45" rpy="0 0 0"/>
  <parent link="base_link"/>
  <child link="suspension_front_right_1"/>
  <axis xyz="1.0 0.0 0.0"/>
  <limit upper="0.087266" lower="-0.174533" effort="100" velocity="100"/>
</joint>

<joint name="Revolute 2" type="fixed">
  <origin xyz="1.925 0.875 -0.45" rpy="0 0 0"/>
  <parent link="base_link"/>
  <child link="suspension_front_left__1"/>
  <axis xyz="-1.0 0.0 0.0"/>
  <limit upper="0.087266" lower="-0.174533" effort="100" velocity="100"/>
</joint>

<joint name="Revolute 3" type="fixed">
  <origin xyz="0.575 0.625 -0.45" rpy="0 0 0"/>
  <parent link="base_link"/>
  <child link="suspension_back_right_1"/>
  <axis xyz="-1.0 0.0 0.0"/>
  <limit upper="0.174533" lower="-0.087266" effort="100" velocity="100"/>
</joint>

<joint name="Revolute 4" type="fixed">
  <origin xyz="0.575 0.875 -0.45" rpy="0 0 0"/>
  <parent link="base_link"/>
  <child link="suspension_back_left_1"/>
  <axis xyz="-1.0 0.0 0.0"/>
  <limit upper="0.087266" lower="-0.174533" effort="100" velocity="100"/>
</joint>

<joint name="back_left_wheel_joint" type="continuous">
  <origin xyz="0.005 0.1625 0.0" rpy="0 0 0"/>
  <parent link="direction_back_left_1"/>
  <child link="rim_back_left_1"/>
  <axis xyz="0.0 1.0 0.0"/>
</joint>

<joint name="back_right_wheel_joint" type="continuous">
  <origin xyz="0.005 -0.1625 0.0" rpy="0 0 0"/>
  <parent link="direction_back_right_1"/>
  <child link="rim_back_right_1"/>
  <axis xyz="0.0 -1.0 0.0"/>
</joint>

<joint name="front_right_wheel_joint" type="continuous">
  <origin xyz="0.0 -0.1625 0.0" rpy="0 0 0"/>
  <parent link="direction_front_right_1"/>
  <child link="rim_front_right_1"/>
  <axis xyz="0.0 -1.0 0.0"/>
</joint>

<joint name="front_left_wheel_joint" type="continuous">
  <origin xyz="0.0 0.1625 0.0" rpy="0 0 0"/>
  <parent link="direction_front_left_1"/>
  <child link="rim_front_left_1"/>
  <axis xyz="0.0 1.0 0.0"/>
</joint>

<joint name="Rigid 9" type="fixed">
  <origin xyz="0.0 -0.047622 0.0" rpy="0 0 0"/>
  <parent link="rim_front_right_1"/>
  <child link="tire_front_right_1"/>
</joint>

<joint name="Rigid 10" type="fixed">
  <origin xyz="0.0 -0.047622 0.0" rpy="0 0 0"/>
  <parent link="rim_back_right_1"/>
  <child link="tire_back_right_1"/>
</joint>

<joint name="Rigid 11" type="fixed">
  <origin xyz="0.0 0.047622 0.0" rpy="0 0 0"/>
  <parent link="rim_back_left_1"/>
  <child link="tire_back_left_1"/>
</joint>

<joint name="Rigid 12" type="fixed">
  <origin xyz="0.0 0.047622 0.0" rpy="0 0 0"/>
  <parent link="rim_front_left_1"/>
  <child link="tire_front_left_1"/>
</joint>

<joint name="Revolute 14" type="fixed">
  <origin xyz="0.0 0.7125 0.0" rpy="0 0 0"/>
  <parent link="suspension_back_left_1"/>
  <child link="direction_back_left_1"/>
</joint>

<joint name="Revolute 15" type="fixed">
  <origin xyz="0.0 -0.7125 0.0" rpy="0 0 0"/>
  <parent link="suspension_back_right_1"/>
  <child link="direction_back_right_1"/>
</joint>

<joint name="Revolute 16" type="fixed">
  <origin xyz="0.0 -0.7125 0.0" rpy="0 0 0"/>
  <parent link="suspension_front_right_1"/>
  <child link="direction_front_right_1"/>
  <axis xyz="0.0 0.0 1.0"/>
  <limit upper="0.523599" lower="-0.523599" effort="100" velocity="100"/>
</joint>

<joint name="Revolute 17" type="fixed">
  <origin xyz="0.0 0.7125 0.0" rpy="0 0 0"/>
  <parent link="suspension_front_left__1"/>
  <child link="direction_front_left_1"/>
  <axis xyz="0.0 0.0 1.0"/>
  <limit upper="0.523599" lower="-0.523599" effort="100" velocity="100"/>
</joint>

<joint name="Rigid 21" type="fixed">
  <origin xyz="1.25 0.75 -0.4" rpy="0 0 0"/>
  <parent link="base_link"/>
  <child link="chasis_1"/>
</joint>

<joint name="Rigid 22" type="fixed">
  <origin xyz="0.6 0.0 1.05" rpy="0 0 0"/>
  <parent link="chasis_1"/>
  <child link="Lidar"/>
</joint>

<joint name="Rigid 23" type="fixed">
  <origin xyz="0.925082 0.0 0.83922" rpy="0 0 0"/>
  <parent link="chasis_1"/>
  <child link="Camara"/>
</joint>

<gazebo>
  <plugin name="ControlPlugin" filename="libcontrol_plugin.so">
    <left_front_wheel_joint>front_left_wheel_joint</left_front_wheel_joint>
    <right_front_wheel_joint>front_right_wheel_joint</right_front_wheel_joint>
    <left_back_wheel_joint>back_left_wheel_joint</left_back_wheel_joint>
    <right_back_wheel_joint>back_right_wheel_joint</right_back_wheel_joint>
  </plugin>
</gazebo>


<gazebo>
    <plugin name="joint_state_publisher" filename="libgazebo_ros_joint_state_publisher.so">
      <ros>
        <namespace>car</namespace>
        <remapping>joint_states:=/joint_states</remapping>
      </ros>
      <update_rate>50</update_rate>
    </plugin>
  </gazebo>

<!-- <gazebo>
  <plugin name="odometryPlugin" filename="libodometry_plugin.so">
    <left_front_wheel_joint>Revolute 17</left_front_wheel_joint>
    <right_front_wheel_joint>Revolute 16</right_front_wheel_joint>
    <left_back_wheel_joint>Revolute 5</left_back_wheel_joint>
    <right_back_wheel_joint>Revolute 6</right_back_wheel_joint>
    <left_front_speed_wheel_joint>Revolute 8</left_front_speed_wheel_joint>
    <right_front_speed_wheel_joint>Revolute 7</right_front_speed_wheel_joint>
  </plugin>
</gazebo> -->





<link name="camera_optical_frame">
</link> 

<joint name="camera_optical_joint" type="fixed">
  <parent link="Camara"/>
  <child link="camera_optical_frame"/>
  <!-- Ajusta rpy para alinear el frame óptico -->
  <origin xyz="0 0 0" rpy="-1.5708 0 -1.5708"/>
</joint>


<link name="base_footprint">
</link> 

<joint name="base_footprint" type="fixed">
  <parent link="base_link"/>
  <child link="base_footprint"/>
  <!-- Ajusta rpy para alinear el frame óptico -->
  <origin xyz="0 0 0" rpy="0 0 0"/>
</joint>


<gazebo>
  <plugin name="imu_controller" filename="libhector_gazebo_ros_imu.so">
  <robotNamespace>car</robotNamespace>
  <updateRate>50.0</updateRate>
  <bodyName>base_link</bodyName>
  <topicName>imu/data</topicName>
  <accelDrift>0.005 0.005 0.005</accelDrift>
  <accelGaussianNoise>0.005 0.005 0.005</accelGaussianNoise>
  <rateDrift>0.005 0.005 0.005 </rateDrift>
  <rateGaussianNoise>0.005 0.005 0.005 </rateGaussianNoise>
  <headingDrift>0.005</headingDrift>
  <headingGaussianNoise>0.005</headingGaussianNoise>
  </plugin>
</gazebo>

<gazebo>
  <plugin name="gps_controller" filename="libhector_gazebo_ros_gps.so">
  <robotNamespace>car</robotNamespace>
  <updateRate>40</updateRate>
  <bodyName>base_link</bodyName>
  <frameId>base_link</frameId>
  <topicName>navsat/fix</topicName>
  <velocityTopicName>navsat/vel</velocityTopicName>
  <referenceLatitude>49.9</referenceLatitude>
  <referenceLongitude>8.9</referenceLongitude>
  <referenceHeading>0</referenceHeading>
  <referenceAltitude>0</referenceAltitude>
  <drift>0.0001 0.0001 0.0001</drift>
  </plugin>
</gazebo>



</robot>