<?xml version="1.0" ?>
<robot name="car" xmlns:xacro="http://www.ros.org/wiki/xacro">

<xacro:include filename="$(find car)/urdf/materials.xacro" />
<xacro:include filename="$(find car)/urdf/car.trans" />
<xacro:include filename="$(find car)/urdf/car.gazebo" />
<xacro:include filename="$(find car)/urdf/car.plugin.xacro" />

<link name="base_link">
  <inertial>
    <origin xyz="0.500073167158104 0.25000000000000006 0.25004231448306036" rpy="0 0 0"/>
    <mass value="1963.3569872059904"/>
    <inertia ixx="81.833055" iyy="204.557202" izz="204.546447" ixy="0.0" iyz="0.0" ixz="-0.036262"/>
  </inertial>
  <visual>
    <origin xyz="0 0 0" rpy="0 0 0"/>
    <geometry>
      <mesh filename="file://$(find car)/meshes/base_link.stl" scale="0.001 0.001 0.001"/>
    </geometry>
    <material name="silver"/>
  </visual>
  <collision>
    <origin xyz="0 0 0" rpy="0 0 0"/>
    <geometry>
      <mesh filename="file://$(find car)/meshes/base_link.stl" scale="0.001 0.001 0.001"/>
    </geometry>
  </collision>
</link>

<link name="Wheel_front_right_1">
  <inertial>
    <origin xyz="0.0 -0.05000000000000001 0.0" rpy="0 0 0"/>
    <mass value="98.6460093227195"/>
    <inertia ixx="1.068665" iyy="1.97292" izz="1.068665" ixy="-0.0" iyz="-0.0" ixz="0.0"/>
  </inertial>
  <visual>
    <origin xyz="-0.875 0.01 -0.15" rpy="0 0 0"/>
    <geometry>
      <mesh filename="file://$(find car)/meshes/Wheel_front_right_1.stl" scale="0.001 0.001 0.001"/>
    </geometry>
    <material name="silver"/>
  </visual>
  <collision>
    <origin xyz="-0.875 0.01 -0.15" rpy="0 0 0"/>
    <geometry>
      <mesh filename="file://$(find car)/meshes/Wheel_front_right_1.stl" scale="0.001 0.001 0.001"/>
    </geometry>
  </collision>
</link>

<link name="Wheel_front_left_1">
  <inertial>
    <origin xyz="0.0 0.050000000000000044 0.0" rpy="0 0 0"/>
    <mass value="98.6460093227195"/>
    <inertia ixx="1.068665" iyy="1.97292" izz="1.068665" ixy="0.0" iyz="0.0" ixz="0.0"/>
  </inertial>
  <visual>
    <origin xyz="-0.875 -0.51 -0.15" rpy="0 0 0"/>
    <geometry>
      <mesh filename="file://$(find car)/meshes/Wheel_front_left_1.stl" scale="0.001 0.001 0.001"/>
    </geometry>
    <material name="silver"/>
  </visual>
  <collision>
    <origin xyz="-0.875 -0.51 -0.15" rpy="0 0 0"/>
    <geometry>
      <mesh filename="file://$(find car)/meshes/Wheel_front_left_1.stl" scale="0.001 0.001 0.001"/>
    </geometry>
  </collision>
</link>

<link name="Wheel_back_left_1">
  <inertial>
    <origin xyz="-2.7755575615628914e-17 0.050000000000000155 0.0" rpy="0 0 0"/>
    <mass value="98.6460093227195"/>
    <inertia ixx="1.068665" iyy="1.97292" izz="1.068665" ixy="0.0" iyz="0.0" ixz="0.0"/>
  </inertial>
  <visual>
    <origin xyz="-0.15 -0.51 -0.15" rpy="0 0 0"/>
    <geometry>
      <mesh filename="file://$(find car)/meshes/Wheel_back_left_1.stl" scale="0.001 0.001 0.001"/>
    </geometry>
    <material name="silver"/>
  </visual>
  <collision>
    <origin xyz="-0.15 -0.51 -0.15" rpy="0 0 0"/>
    <geometry>
      <mesh filename="file://$(find car)/meshes/Wheel_back_left_1.stl" scale="0.001 0.001 0.001"/>
    </geometry>
  </collision>
</link>

<link name="Wheel_back_right_1">
  <inertial>
    <origin xyz="-2.7755575615628914e-17 -0.05000000000000001 0.0" rpy="0 0 0"/>
    <mass value="98.6460093227195"/>
    <inertia ixx="1.068665" iyy="1.97292" izz="1.068665" ixy="0.0" iyz="-0.0" ixz="0.0"/>
  </inertial>
  <visual>
    <origin xyz="-0.15 0.01 -0.15" rpy="0 0 0"/>
    <geometry>
      <mesh filename="file://$(find car)/meshes/Wheel_back_right_1.stl" scale="0.001 0.001 0.001"/>
    </geometry>
    <material name="silver"/>
  </visual>
  <collision>
    <origin xyz="-0.15 0.01 -0.15" rpy="0 0 0"/>
    <geometry>
      <mesh filename="file://$(find car)/meshes/Wheel_back_right_1.stl" scale="0.001 0.001 0.001"/>
    </geometry>
  </collision>
</link>

<link name="Laser_1">
  <inertial>
    <origin xyz="-2.220446049250313e-16 5.551115123125783e-17 0.03499999999999992" rpy="0 0 0"/>
    <mass value="52.86809562139498"/>
    <inertia ixx="0.426359" iyy="0.426359" izz="0.809543" ixy="0.0" iyz="-0.0" ixz="0.0"/>
  </inertial>
  <visual>
    <origin xyz="-0.8 -0.25 -0.53" rpy="0 0 0"/>
    <geometry>
      <mesh filename="file://$(find car)/meshes/Laser_1.stl" scale="0.001 0.001 0.001"/>
    </geometry>
    <material name="silver"/>
  </visual>
  <collision>
    <origin xyz="-0.8 -0.25 -0.53" rpy="0 0 0"/>
    <geometry>
      <mesh filename="file://$(find car)/meshes/Laser_1.stl" scale="0.001 0.001 0.001"/>
    </geometry>
  </collision>
</link>

<joint name="revolute_right_wheel" type="continuous">
  <origin xyz="0.875 -0.01 0.15" rpy="0 0 0"/>
  <parent link="base_link"/>
  <child link="Wheel_front_right_1"/>
  <axis xyz="0.0 -1.0 0.0"/>
</joint>

<joint name="revolute_left_wheel" type="continuous">
  <origin xyz="0.875 0.51 0.15" rpy="0 0 0"/>
  <parent link="base_link"/>
  <child link="Wheel_front_left_1"/>
  <axis xyz="0.0 1.0 0.0"/>
</joint>

<joint name="revolute_back_left_wheel" type="continuous">
  <origin xyz="0.15 0.51 0.15" rpy="0 0 0"/>
  <parent link="base_link"/>
  <child link="Wheel_back_left_1"/>
  <axis xyz="0.0 1.0 0.0"/>
</joint>

<joint name="revolute_back_right_wheel" type="continuous">
  <origin xyz="0.15 -0.01 0.15" rpy="0 0 0"/>
  <parent link="base_link"/>
  <child link="Wheel_back_right_1"/>
  <axis xyz="0.0 -1.0 0.0"/>
</joint>

<joint name="revolute_laser" type="continuous">
  <origin xyz="0.8 0.25 0.53" rpy="0 0 0"/>
  <parent link="base_link"/>
  <child link="Laser_1"/>
  <axis xyz="0.0 0.0 1.0"/>
</joint>

</robot>
