<?xml version="1.0" ?>
<robot name="car" xmlns:xacro="http://www.ros.org/wiki/xacro">

<xacro:include filename="$(find car_description)/urdf/materials.xacro" />
<xacro:include filename="$(find car_description)/urdf/car.trans" />
<xacro:include filename="$(find car_description)/urdf/car.gazebo" />
<xacro:include filename="$(find car_description)/urdf/car.plugin.xacro" />

<link name="base_link">
  <inertial>
    <origin xyz="0.02503210561392206 -0.01250000000041644 0.0035096585129147538" rpy="0 0 0"/>
    <mass value="0.06894028040642299"/>
    <inertia ixx="4e-06" iyy="1.5e-05" izz="1.8e-05" ixy="0.0" iyz="0.0" ixz="-0.0"/>
  </inertial>
  <visual>
    <origin xyz="0 0 0" rpy="0 0 0"/>
    <geometry>
      <mesh filename="file://$(find car_description)/meshes/base_link.stl" scale="0.001 0.001 0.001"/>
    </geometry>
    <material name="silver"/>
  </visual>
  <collision>
    <origin xyz="0 0 0" rpy="0 0 0"/>
    <geometry>
      <mesh filename="file://$(find car_description)/meshes/base_link.stl" scale="0.001 0.001 0.001"/>
    </geometry>
  </collision>
</link>

<link name="wheel_right_back_1">
  <inertial>
    <origin xyz="1.1920929174347172e-10 -0.0035000000000000066 5.9604635463395e-11" rpy="0 0 0"/>
    <mass value="0.00621469877254378"/>
    <inertia ixx="0.0" iyy="0.0" izz="0.0" ixy="0.0" iyz="0.0" ixz="-0.0"/>
  </inertial>
  <visual>
    <origin xyz="-0.008 0.026 -0.004" rpy="0 0 0"/>
    <geometry>
      <mesh filename="file://$(find car_description)/meshes/wheel_right_back_1.stl" scale="0.001 0.001 0.001"/>
    </geometry>
    <material name="silver"/>
  </visual>
  <collision>
    <origin xyz="-0.008 0.026 -0.004" rpy="0 0 0"/>
    <geometry>
      <mesh filename="file://$(find car_description)/meshes/wheel_right_back_1.stl" scale="0.001 0.001 0.001"/>
    </geometry>
  </collision>
</link>

<link name="wheel_right_front_1">
  <inertial>
    <origin xyz="5.960464413701239e-10 -0.0035000000000000135 5.960463719811848e-11" rpy="0 0 0"/>
    <mass value="0.006214698772543783"/>
    <inertia ixx="0.0" iyy="0.0" izz="0.0" ixy="-0.0" iyz="0.0" ixz="0.0"/>
  </inertial>
  <visual>
    <origin xyz="-0.04 0.026 -0.004" rpy="0 0 0"/>
    <geometry>
      <mesh filename="file://$(find car_description)/meshes/wheel_right_front_1.stl" scale="0.001 0.001 0.001"/>
    </geometry>
    <material name="silver"/>
  </visual>
  <collision>
    <origin xyz="-0.04 0.026 -0.004" rpy="0 0 0"/>
    <geometry>
      <mesh filename="file://$(find car_description)/meshes/wheel_right_front_1.stl" scale="0.001 0.001 0.001"/>
    </geometry>
  </collision>
</link>

<link name="wheel_left_front_1">
  <inertial>
    <origin xyz="5.960464483090178e-10 0.0034999999999999988 5.96046467390976e-11" rpy="0 0 0"/>
    <mass value="0.006214698772543782"/>
    <inertia ixx="0.0" iyy="0.0" izz="0.0" ixy="0.0" iyz="-0.0" ixz="-0.0"/>
  </inertial>
  <visual>
    <origin xyz="-0.04 -0.001 -0.004" rpy="0 0 0"/>
    <geometry>
      <mesh filename="file://$(find car_description)/meshes/wheel_left_front_1.stl" scale="0.001 0.001 0.001"/>
    </geometry>
    <material name="silver"/>
  </visual>
  <collision>
    <origin xyz="-0.04 -0.001 -0.004" rpy="0 0 0"/>
    <geometry>
      <mesh filename="file://$(find car_description)/meshes/wheel_left_front_1.stl" scale="0.001 0.001 0.001"/>
    </geometry>
  </collision>
</link>

<link name="wheel_left_back_1">
  <inertial>
    <origin xyz="1.1920929000874825e-10 0.0034999999999999996 5.960464500437412e-11" rpy="0 0 0"/>
    <mass value="0.006214698772543781"/>
    <inertia ixx="0.0" iyy="0.0" izz="0.0" ixy="-0.0" iyz="0.0" ixz="-0.0"/>
  </inertial>
  <visual>
    <origin xyz="-0.008 -0.001 -0.004" rpy="0 0 0"/>
    <geometry>
      <mesh filename="file://$(find car_description)/meshes/wheel_left_back_1.stl" scale="0.001 0.001 0.001"/>
    </geometry>
    <material name="silver"/>
  </visual>
  <collision>
    <origin xyz="-0.008 -0.001 -0.004" rpy="0 0 0"/>
    <geometry>
      <mesh filename="file://$(find car_description)/meshes/wheel_left_back_1.stl" scale="0.001 0.001 0.001"/>
    </geometry>
  </collision>
</link>

<link name="laser_1">
  <inertial>
    <origin xyz="5.960464552479117e-10 -1.862645159639298e-10 0.0024999999999999953" rpy="0 0 0"/>
    <mass value="0.004439070551816985"/>
    <inertia ixx="0.0" iyy="0.0" izz="0.0" ixy="0.0" iyz="0.0" ixz="-0.0"/>
  </inertial>
  <visual>
    <origin xyz="-0.04 0.0125 -0.008" rpy="0 0 0"/>
    <geometry>
      <mesh filename="file://$(find car_description)/meshes/laser_1.stl" scale="0.001 0.001 0.001"/>
    </geometry>
    <material name="silver"/>
  </visual>
  <collision>
    <origin xyz="-0.04 0.0125 -0.008" rpy="0 0 0"/>
    <geometry>
      <mesh filename="file://$(find car_description)/meshes/laser_1.stl" scale="0.001 0.001 0.001"/>
    </geometry>
  </collision>
</link>

<joint name="Revolute 9" type="continuous">
  <origin xyz="0.008 -0.026 0.004" rpy="0 0 0"/>
  <parent link="base_link"/>
  <child link="wheel_right_back_1"/>
  <axis xyz="0.0 -1.0 0.0"/>
</joint>

<joint name="Revolute 10" type="continuous">
  <origin xyz="0.04 -0.026 0.004" rpy="0 0 0"/>
  <parent link="base_link"/>
  <child link="wheel_right_front_1"/>
  <axis xyz="0.0 -1.0 0.0"/>
</joint>

<joint name="Revolute 11" type="continuous">
  <origin xyz="0.04 0.001 0.004" rpy="0 0 0"/>
  <parent link="base_link"/>
  <child link="wheel_left_front_1"/>
  <axis xyz="0.0 1.0 0.0"/>
</joint>

<joint name="Revolute 12" type="continuous">
  <origin xyz="0.008 0.001 0.004" rpy="0 0 0"/>
  <parent link="base_link"/>
  <child link="wheel_left_back_1"/>
  <axis xyz="0.0 1.0 0.0"/>
</joint>

<joint name="Revolute 13" type="continuous">
  <origin xyz="0.04 -0.0125 0.008" rpy="0 0 0"/>
  <parent link="base_link"/>
  <child link="laser_1"/>
  <axis xyz="0.0 0.0 1.0"/>
</joint>

</robot>
