<?xml version="1.0" ?>
<robot name="car" xmlns:xacro="http://www.ros.org/wiki/xacro">

<xacro:include filename="$(find car)/urdf/materials.xacro" />
<xacro:include filename="$(find car)/urdf/car.trans" />
<xacro:include filename="$(find car)/urdf/car.gazebo" />
<link name="base_link">
  <inertial>
    <origin xyz="1.2499999999999978 0.7500000000000009 -0.2545254750760079" rpy="0 0 0"/>
    <mass value="269.08335757252974"/>
    <inertia ixx="59.92484" iyy="164.14927" izz="209.699486" ixy="-0.0" iyz="0.0" ixz="-0.0"/>
  </inertial>
  <visual>
    <origin xyz="0 0 0" rpy="0 0 0"/>
    <geometry>
      <mesh filename="file://$(find car)/meshes/base_link.stl" scale="0.001 0.001 0.001"/>
    </geometry>
    <material name="silver"/>
  </visual>
  <collision>
    <origin xyz="0 0 0" rpy="0 0 0"/>
    <geometry>
      <mesh filename="file://$(find car)/meshes/base_link.stl" scale="0.001 0.001 0.001"/>
    </geometry>
  </collision>
</link>

<link name="direction_back_right_1">
  <inertial>
    <origin xyz="3.3409086608315874e-10 -0.0928245439091594 2.3407225085980699e-07" rpy="0 0 0"/>
    <mass value="8.30107936784585"/>
    <inertia ixx="0.025244" iyy="0.013095" izz="0.028812" ixy="-0.0" iyz="-0.0" ixz="-0.0"/>
  </inertial>
  <visual>
    <origin xyz="-0.35 0.07 0.481229" rpy="0 0 0"/>
    <geometry>
      <mesh filename="file://$(find car)/meshes/direction_back_right_1.stl" scale="0.001 0.001 0.001"/>
    </geometry>
    <material name="silver"/>
  </visual>
  <collision>
    <origin xyz="-0.35 0.07 0.481229" rpy="0 0 0"/>
    <geometry>
      <mesh filename="file://$(find car)/meshes/direction_back_right_1.stl" scale="0.001 0.001 0.001"/>
    </geometry>
  </collision>
</link>

<link name="direction_back_left_1">
  <inertial>
    <origin xyz="-3.885780586188048e-16 0.09282454447738075 2.3407225102634044e-07" rpy="0 0 0"/>
    <mass value="8.301079315724648"/>
    <inertia ixx="0.025244" iyy="0.013095" izz="0.028812" ixy="0.0" iyz="0.0" ixz="0.0"/>
  </inertial>
  <visual>
    <origin xyz="-0.35 -1.57 0.481229" rpy="0 0 0"/>
    <geometry>
      <mesh filename="file://$(find car)/meshes/direction_back_left_1.stl" scale="0.001 0.001 0.001"/>
    </geometry>
    <material name="silver"/>
  </visual>
  <collision>
    <origin xyz="-0.35 -1.57 0.481229" rpy="0 0 0"/>
    <geometry>
      <mesh filename="file://$(find car)/meshes/direction_back_left_1.stl" scale="0.001 0.001 0.001"/>
    </geometry>
  </collision>
</link>

<link name="direction_front_left_1">
  <inertial>
    <origin xyz="4.440892098500626e-16 0.09282454447738075 2.3407225091531814e-07" rpy="0 0 0"/>
    <mass value="8.301079315724627"/>
    <inertia ixx="0.025244" iyy="0.013095" izz="0.028812" ixy="0.0" iyz="0.0" ixz="0.0"/>
  </inertial>
  <visual>
    <origin xyz="-2.15 -1.57 0.481229" rpy="0 0 0"/>
    <geometry>
      <mesh filename="file://$(find car)/meshes/direction_front_left_1.stl" scale="0.001 0.001 0.001"/>
    </geometry>
    <material name="silver"/>
  </visual>
  <collision>
    <origin xyz="-2.15 -1.57 0.481229" rpy="0 0 0"/>
    <geometry>
      <mesh filename="file://$(find car)/meshes/direction_front_left_1.stl" scale="0.001 0.001 0.001"/>
    </geometry>
  </collision>
</link>

<link name="direction_front_right_1">
  <inertial>
    <origin xyz="2.220446049250313e-15 -0.09282454447738067 2.3407225041571778e-07" rpy="0 0 0"/>
    <mass value="8.301079315724627"/>
    <inertia ixx="0.025244" iyy="0.013095" izz="0.028812" ixy="-0.0" iyz="0.0" ixz="-0.0"/>
  </inertial>
  <visual>
    <origin xyz="-2.15 0.07 0.481229" rpy="0 0 0"/>
    <geometry>
      <mesh filename="file://$(find car)/meshes/direction_front_right_1.stl" scale="0.001 0.001 0.001"/>
    </geometry>
    <material name="silver"/>
  </visual>
  <collision>
    <origin xyz="-2.15 0.07 0.481229" rpy="0 0 0"/>
    <geometry>
      <mesh filename="file://$(find car)/meshes/direction_front_right_1.stl" scale="0.001 0.001 0.001"/>
    </geometry>
  </collision>
</link>

<link name="rim_back_right_1">
  <inertial>
    <origin xyz="-6.193390829078993e-07 -0.0444583218626792 -3.5654687319808254e-06" rpy="0 0 0"/>
    <mass value="35.26125455495801"/>
    <inertia ixx="0.833786" iyy="1.48872" izz="0.833785" ixy="-1e-06" iyz="-3e-06" ixz="-3e-06"/>
  </inertial>
  <visual>
    <origin xyz="-0.35 0.225 0.481229" rpy="0 0 0"/>
    <geometry>
      <mesh filename="file://$(find car)/meshes/rim_back_right_1.stl" scale="0.001 0.001 0.001"/>
    </geometry>
    <material name="silver"/>
  </visual>
  <collision>
    <origin xyz="-0.35 0.225 0.481229" rpy="0 0 0"/>
    <geometry>
      <mesh filename="file://$(find car)/meshes/rim_back_right_1.stl" scale="0.001 0.001 0.001"/>
    </geometry>
  </collision>
</link>

<link name="tire_back_right_1">
  <inertial>
    <origin xyz="3.3306690738754696e-16 1.865424177349695e-07 2.3407225080429583e-07" rpy="0 0 0"/>
    <mass value="72.81552294350425"/>
    <inertia ixx="4.088543" iyy="7.430415" izz="4.088543" ixy="-0.0" iyz="0.0" ixz="-0.0"/>
  </inertial>
  <visual>
    <origin xyz="-0.35 0.272622 0.481229" rpy="0 0 0"/>
    <geometry>
      <mesh filename="file://$(find car)/meshes/tire_back_right_1.stl" scale="0.001 0.001 0.001"/>
    </geometry>
    <material name="silver"/>
  </visual>
  <collision>
    <origin xyz="-0.35 0.272622 0.481229" rpy="0 0 0"/>
    <geometry>
      <mesh filename="file://$(find car)/meshes/tire_back_right_1.stl" scale="0.001 0.001 0.001"/>
    </geometry>
  </collision>
</link>

<link name="rim_back_left_1">
  <inertial>
    <origin xyz="-6.19339082796877e-07 0.04445832186264642 4.033613232867772e-06" rpy="0 0 0"/>
    <mass value="35.26125455495529"/>
    <inertia ixx="0.833786" iyy="1.48872" izz="0.833785" ixy="1e-06" iyz="-3e-06" ixz="3e-06"/>
  </inertial>
  <visual>
    <origin xyz="-0.35 -1.725 0.481229" rpy="0 0 0"/>
    <geometry>
      <mesh filename="file://$(find car)/meshes/rim_back_left_1.stl" scale="0.001 0.001 0.001"/>
    </geometry>
    <material name="silver"/>
  </visual>
  <collision>
    <origin xyz="-0.35 -1.725 0.481229" rpy="0 0 0"/>
    <geometry>
      <mesh filename="file://$(find car)/meshes/rim_back_left_1.stl" scale="0.001 0.001 0.001"/>
    </geometry>
  </collision>
</link>

<link name="tire_back_left_1">
  <inertial>
    <origin xyz="3.3306690738754696e-16 -1.8654241507043423e-07 2.3407225080429583e-07" rpy="0 0 0"/>
    <mass value="72.81552294350425"/>
    <inertia ixx="4.088543" iyy="7.430415" izz="4.088543" ixy="-0.0" iyz="0.0" ixz="-0.0"/>
  </inertial>
  <visual>
    <origin xyz="-0.35 -1.772622 0.481229" rpy="0 0 0"/>
    <geometry>
      <mesh filename="file://$(find car)/meshes/tire_back_left_1.stl" scale="0.001 0.001 0.001"/>
    </geometry>
    <material name="silver"/>
  </visual>
  <collision>
    <origin xyz="-0.35 -1.772622 0.481229" rpy="0 0 0"/>
    <geometry>
      <mesh filename="file://$(find car)/meshes/tire_back_left_1.stl" scale="0.001 0.001 0.001"/>
    </geometry>
  </collision>
</link>

<link name="rim_front_left_1">
  <inertial>
    <origin xyz="-6.193390835740331e-07 0.04445832186254606 4.033613235310263e-06" rpy="0 0 0"/>
    <mass value="35.26125455494993"/>
    <inertia ixx="0.833786" iyy="1.48872" izz="0.833785" ixy="1e-06" iyz="-3e-06" ixz="3e-06"/>
  </inertial>
  <visual>
    <origin xyz="-2.15 -1.725 0.481229" rpy="0 0 0"/>
    <geometry>
      <mesh filename="file://$(find car)/meshes/rim_front_left_1.stl" scale="0.001 0.001 0.001"/>
    </geometry>
    <material name="silver"/>
  </visual>
  <collision>
    <origin xyz="-2.15 -1.725 0.481229" rpy="0 0 0"/>
    <geometry>
      <mesh filename="file://$(find car)/meshes/rim_front_left_1.stl" scale="0.001 0.001 0.001"/>
    </geometry>
  </collision>
</link>

<link name="rim_front_right_1">
  <inertial>
    <origin xyz="-6.193390862385684e-07 -0.044458321862509836 -3.5654687342567826e-06" rpy="0 0 0"/>
    <mass value="35.26125455495071"/>
    <inertia ixx="0.833786" iyy="1.48872" izz="0.833785" ixy="-1e-06" iyz="-3e-06" ixz="-3e-06"/>
  </inertial>
  <visual>
    <origin xyz="-2.15 0.225 0.481229" rpy="0 0 0"/>
    <geometry>
      <mesh filename="file://$(find car)/meshes/rim_front_right_1.stl" scale="0.001 0.001 0.001"/>
    </geometry>
    <material name="silver"/>
  </visual>
  <collision>
    <origin xyz="-2.15 0.225 0.481229" rpy="0 0 0"/>
    <geometry>
      <mesh filename="file://$(find car)/meshes/rim_front_right_1.stl" scale="0.001 0.001 0.001"/>
    </geometry>
  </collision>
</link>

<link name="tire_front_right_1">
  <inertial>
    <origin xyz="1.3322676295501878e-15 1.865424186231479e-07 2.3407225080429583e-07" rpy="0 0 0"/>
    <mass value="72.81552294350425"/>
    <inertia ixx="4.088543" iyy="7.430415" izz="4.088543" ixy="-0.0" iyz="0.0" ixz="0.0"/>
  </inertial>
  <visual>
    <origin xyz="-2.15 0.272622 0.481229" rpy="0 0 0"/>
    <geometry>
      <mesh filename="file://$(find car)/meshes/tire_front_right_1.stl" scale="0.001 0.001 0.001"/>
    </geometry>
    <material name="silver"/>
  </visual>
  <collision>
    <origin xyz="-2.15 0.272622 0.481229" rpy="0 0 0"/>
    <geometry>
      <mesh filename="file://$(find car)/meshes/tire_front_right_1.stl" scale="0.001 0.001 0.001"/>
    </geometry>
  </collision>
</link>

<link name="tire_front_left_1">
  <inertial>
    <origin xyz="3.9968028886505635e-15 -1.8654242395221843e-07 2.3407225091531814e-07" rpy="0 0 0"/>
    <mass value="72.81552294350426"/>
    <inertia ixx="4.088543" iyy="7.430415" izz="4.088543" ixy="0.0" iyz="0.0" ixz="-0.0"/>
  </inertial>
  <visual>
    <origin xyz="-2.15 -1.772622 0.481229" rpy="0 0 0"/>
    <geometry>
      <mesh filename="file://$(find car)/meshes/tire_front_left_1.stl" scale="0.001 0.001 0.001"/>
    </geometry>
    <material name="silver"/>
  </visual>
  <collision>
    <origin xyz="-2.15 -1.772622 0.481229" rpy="0 0 0"/>
    <geometry>
      <mesh filename="file://$(find car)/meshes/tire_front_left_1.stl" scale="0.001 0.001 0.001"/>
    </geometry>
  </collision>
</link>

<joint name="Direction_right_back" type="continuous">
  <origin xyz="0.35 -0.07 -0.481229" rpy="0 0 0"/>
  <parent link="base_link"/>
  <child link="direction_back_right_1"/>
  <axis xyz="0.0 0.0 1.0"/>
</joint>

<joint name="Direction_left_back" type="continuous">
  <origin xyz="0.35 1.57 -0.481229" rpy="0 0 0"/>
  <parent link="base_link"/>
  <child link="direction_back_left_1"/>
  <axis xyz="0.0 0.0 1.0"/>
</joint>

<joint name="Direction_left_front" type="revolute">
  <origin xyz="2.15 1.57 -0.481229" rpy="0 0 0"/>
  <parent link="base_link"/>
  <child link="direction_front_left_1"/>
  <axis xyz="0.0 0.0 -1.0"/>
  <limit effort="10.0" velocity="1.0" lower="-1.57" upper="1.57"/>
</joint>

<joint name="Direction_right_front" type="revolute">
  <origin xyz="2.15 -0.07 -0.481229" rpy="0 0 0"/>
  <parent link="base_link"/>
  <child link="direction_front_right_1"/>
  <axis xyz="0.0 0.0 -1.0"/>
  <limit effort="10.0" velocity="1.0" lower="-1.57" upper="1.57"/>
</joint>

<joint name="Revolute_right_back" type="continuous">
  <origin xyz="0.0 -0.155 0.0" rpy="0 0 0"/>
  <parent link="direction_back_right_1"/>
  <child link="rim_back_right_1"/>
  <axis xyz="0.0 -1.0 0.0"/>
</joint>

<joint name="Rigid 18" type="fixed">
  <origin xyz="0.0 -0.047622 0.0" rpy="0 0 0"/>
  <parent link="rim_back_right_1"/>
  <child link="tire_back_right_1"/>
</joint>

<joint name="Revolute_left_back" type="continuous">
  <origin xyz="0.0 0.155 0.0" rpy="0 0 0"/>
  <parent link="direction_back_left_1"/>
  <child link="rim_back_left_1"/>
  <axis xyz="0.0 1.0 0.0"/>
</joint>

<joint name="Rigid 20" type="fixed">
  <origin xyz="0.0 0.047622 0.0" rpy="0 0 0"/>
  <parent link="rim_back_left_1"/>
  <child link="tire_back_left_1"/>
</joint>

<joint name="Revolute_left_front" type="continuous">
  <origin xyz="0.0 0.155 0.0" rpy="0 0 0"/>
  <parent link="direction_front_left_1"/>
  <child link="rim_front_left_1"/>
  <axis xyz="0.0 1.0 0.0"/>
</joint>

<joint name="Revolute_right_front" type="continuous">
  <origin xyz="0.0 -0.155 0.0" rpy="0 0 0"/>
  <parent link="direction_front_right_1"/>
  <child link="rim_front_right_1"/>
  <axis xyz="0.0 -1.0 0.0"/>
</joint>

<joint name="Rigid 23" type="fixed">
  <origin xyz="0.0 -0.047622 0.0" rpy="0 0 0"/>
  <parent link="rim_front_right_1"/>
  <child link="tire_front_right_1"/>
</joint>

<joint name="Rigid 24" type="fixed">
  <origin xyz="0.0 0.047622 0.0" rpy="0 0 0"/>
  <parent link="rim_front_left_1"/>
  <child link="tire_front_left_1"/>
</joint>


<gazebo>
  <plugin name="control_plugin" filename="libcontrol_plugin.so">
    <joint_name>Revolute_right_front</joint_name>
  </plugin>
</gazebo>


</robot>
